2025-06-15 01:15:34,588 INFO    Thread-11 :40186 [wandb_setup.py:_flush():81] Current SDK version is 0.20.1
2025-06-15 01:15:34,588 INFO    Thread-11 :40186 [wandb_setup.py:_flush():81] Configure stats pid to 40186
2025-06-15 01:15:34,588 INFO    Thread-11 :40186 [wandb_setup.py:_flush():81] Loading settings from /home/parastoo/.config/wandb/settings
2025-06-15 01:15:34,588 INFO    Thread-11 :40186 [wandb_setup.py:_flush():81] Loading settings from /home/parastoo/Desktop/new1/RL/training/wandb/settings
2025-06-15 01:15:34,588 INFO    Thread-11 :40186 [wandb_setup.py:_flush():81] Loading settings from environment variables
2025-06-15 01:15:34,588 INFO    Thread-11 :40186 [wandb_init.py:setup_run_log_directory():703] Logging user logs to /home/parastoo/Desktop/new1/RL/training/wandb/run-20250615_011534-ejw42ieu/logs/debug.log
2025-06-15 01:15:34,588 INFO    Thread-11 :40186 [wandb_init.py:setup_run_log_directory():704] Logging internal logs to /home/parastoo/Desktop/new1/RL/training/wandb/run-20250615_011534-ejw42ieu/logs/debug-internal.log
2025-06-15 01:15:34,588 INFO    Thread-11 :40186 [wandb_init.py:init():831] calling init triggers
2025-06-15 01:15:34,588 INFO    Thread-11 :40186 [wandb_init.py:init():836] wandb.init called with sweep_config: {'batch_size': 49, 'gae_lambda': 0.9362560586063364, 'gamma': 0.9045889872293914, 'learning_rate': 0.0005333850921463625, 'n_epochs': 12}
config: {'method': 'random', 'metric': {'name': 'mean_mean_reward', 'goal': 'maximize'}, 'parameters': {'learning_rate': {'min': 3e-05, 'max': 0.003}, 'gamma': {'min': 0.9, 'max': 0.9999}, 'batch_size': {'min': 32, 'max': 128}, 'n_epochs': {'min': 5, 'max': 20}, 'gae_lambda': {'min': 0.85, 'max': 0.999}}, '_wandb': {}}
2025-06-15 01:15:34,588 INFO    Thread-11 :40186 [wandb_init.py:init():872] starting backend
2025-06-15 01:15:34,835 INFO    Thread-11 :40186 [wandb_init.py:init():875] sending inform_init request
2025-06-15 01:15:34,836 INFO    Thread-11 :40186 [wandb_init.py:init():883] backend started and connected
2025-06-15 01:15:34,836 INFO    Thread-11 :40186 [wandb_run.py:_config_callback():1358] config_cb None None {'batch_size': 49, 'gae_lambda': 0.9362560586063364, 'gamma': 0.9045889872293914, 'learning_rate': 0.0005333850921463625, 'n_epochs': 12}
2025-06-15 01:15:34,839 INFO    Thread-11 :40186 [wandb_init.py:init():956] updated telemetry
2025-06-15 01:15:34,888 INFO    Thread-11 :40186 [wandb_init.py:init():980] communicating run to backend with 90.0 second timeout
2025-06-15 01:15:35,336 INFO    Thread-11 :40186 [wandb_init.py:init():1032] starting run threads in backend
2025-06-15 01:15:35,381 INFO    Thread-11 :40186 [wandb_run.py:_console_start():2453] atexit reg
2025-06-15 01:15:35,381 INFO    Thread-11 :40186 [wandb_run.py:_redirect():2301] redirect: wrap_raw
2025-06-15 01:15:35,381 INFO    Thread-11 :40186 [wandb_run.py:_redirect():2370] Wrapping output streams.
2025-06-15 01:15:35,381 INFO    Thread-11 :40186 [wandb_run.py:_redirect():2393] Redirects installed.
2025-06-15 01:15:35,381 INFO    Thread-11 :40186 [wandb_init.py:init():1078] run started, returning control to user process
2025-06-15 01:32:45,344 INFO    Thread-1  :40186 [retry.py:__call__():173] [no run ID] Retry attempt failed:
Traceback (most recent call last):
  File "/home/parastoo/anaconda3/envs/rl/lib/python3.8/site-packages/urllib3/connection.py", line 199, in _new_conn
    sock = connection.create_connection(
  File "/home/parastoo/anaconda3/envs/rl/lib/python3.8/site-packages/urllib3/util/connection.py", line 60, in create_connection
    for res in socket.getaddrinfo(host, port, family, socket.SOCK_STREAM):
  File "/home/parastoo/anaconda3/envs/rl/lib/python3.8/socket.py", line 930, in getaddrinfo
    for res in _socket.getaddrinfo(host, port, family, type, proto, flags):
socket.gaierror: [Errno -3] Temporary failure in name resolution

The above exception was the direct cause of the following exception:

Traceback (most recent call last):
  File "/home/parastoo/anaconda3/envs/rl/lib/python3.8/site-packages/urllib3/connectionpool.py", line 789, in urlopen
    response = self._make_request(
  File "/home/parastoo/anaconda3/envs/rl/lib/python3.8/site-packages/urllib3/connectionpool.py", line 490, in _make_request
    raise new_e
  File "/home/parastoo/anaconda3/envs/rl/lib/python3.8/site-packages/urllib3/connectionpool.py", line 466, in _make_request
    self._validate_conn(conn)
  File "/home/parastoo/anaconda3/envs/rl/lib/python3.8/site-packages/urllib3/connectionpool.py", line 1095, in _validate_conn
    conn.connect()
  File "/home/parastoo/anaconda3/envs/rl/lib/python3.8/site-packages/urllib3/connection.py", line 693, in connect
    self.sock = sock = self._new_conn()
  File "/home/parastoo/anaconda3/envs/rl/lib/python3.8/site-packages/urllib3/connection.py", line 206, in _new_conn
    raise NameResolutionError(self.host, self, e) from e
urllib3.exceptions.NameResolutionError: <urllib3.connection.HTTPSConnection object at 0x7fd24c158790>: Failed to resolve 'api.wandb.ai' ([Errno -3] Temporary failure in name resolution)

The above exception was the direct cause of the following exception:

Traceback (most recent call last):
  File "/home/parastoo/anaconda3/envs/rl/lib/python3.8/site-packages/requests/adapters.py", line 667, in send
    resp = conn.urlopen(
  File "/home/parastoo/anaconda3/envs/rl/lib/python3.8/site-packages/urllib3/connectionpool.py", line 843, in urlopen
    retries = retries.increment(
  File "/home/parastoo/anaconda3/envs/rl/lib/python3.8/site-packages/urllib3/util/retry.py", line 519, in increment
    raise MaxRetryError(_pool, url, reason) from reason  # type: ignore[arg-type]
urllib3.exceptions.MaxRetryError: HTTPSConnectionPool(host='api.wandb.ai', port=443): Max retries exceeded with url: /graphql (Caused by NameResolutionError("<urllib3.connection.HTTPSConnection object at 0x7fd24c158790>: Failed to resolve 'api.wandb.ai' ([Errno -3] Temporary failure in name resolution)"))

During handling of the above exception, another exception occurred:

Traceback (most recent call last):
  File "/home/parastoo/anaconda3/envs/rl/lib/python3.8/site-packages/wandb/sdk/lib/retry.py", line 134, in __call__
    result = self._call_fn(*args, **kwargs)
  File "/home/parastoo/anaconda3/envs/rl/lib/python3.8/site-packages/wandb/sdk/internal/internal_api.py", line 396, in execute
    return self.client.execute(*args, **kwargs)  # type: ignore
  File "/home/parastoo/anaconda3/envs/rl/lib/python3.8/site-packages/wandb/vendor/gql-0.2.0/wandb_gql/client.py", line 52, in execute
    result = self._get_result(document, *args, **kwargs)
  File "/home/parastoo/anaconda3/envs/rl/lib/python3.8/site-packages/wandb/vendor/gql-0.2.0/wandb_gql/client.py", line 60, in _get_result
    return self.transport.execute(document, *args, **kwargs)
  File "/home/parastoo/anaconda3/envs/rl/lib/python3.8/site-packages/wandb/sdk/lib/gql_request.py", line 58, in execute
    request = self.session.post(self.url, **post_args)
  File "/home/parastoo/anaconda3/envs/rl/lib/python3.8/site-packages/requests/sessions.py", line 637, in post
    return self.request("POST", url, data=data, json=json, **kwargs)
  File "/home/parastoo/anaconda3/envs/rl/lib/python3.8/site-packages/requests/sessions.py", line 589, in request
    resp = self.send(prep, **send_kwargs)
  File "/home/parastoo/anaconda3/envs/rl/lib/python3.8/site-packages/requests/sessions.py", line 703, in send
    r = adapter.send(request, **kwargs)
  File "/home/parastoo/anaconda3/envs/rl/lib/python3.8/site-packages/requests/adapters.py", line 700, in send
    raise ConnectionError(e, request=request)
requests.exceptions.ConnectionError: HTTPSConnectionPool(host='api.wandb.ai', port=443): Max retries exceeded with url: /graphql (Caused by NameResolutionError("<urllib3.connection.HTTPSConnection object at 0x7fd24c158790>: Failed to resolve 'api.wandb.ai' ([Errno -3] Temporary failure in name resolution)"))
2025-06-15 01:45:35,981 INFO    Thread-11 :40186 [wandb_run.py:_finish():2219] finishing run parastoohashemi78-politecnico-di-torino/ppo_sweep_ss/ejw42ieu
2025-06-15 01:45:35,981 INFO    Thread-11 :40186 [wandb_run.py:_atexit_cleanup():2418] got exitcode: 0
2025-06-15 01:45:35,982 INFO    Thread-11 :40186 [wandb_run.py:_restore():2400] restore
2025-06-15 01:45:35,982 INFO    Thread-11 :40186 [wandb_run.py:_restore():2406] restore done
2025-06-15 07:23:05,640 INFO    Thread-11 :40186 [wandb_run.py:_footer_history_summary_info():4000] rendering history
2025-06-15 07:23:05,640 INFO    Thread-11 :40186 [wandb_run.py:_footer_history_summary_info():4032] rendering summary
2025-06-15 07:23:05,640 INFO    Thread-11 :40186 [wandb_run.py:_footer_sync_info():3961] logging synced files
